<?xml version="1.0"?>
<robot name="modified_stewart">
  <link name="plane">
    <visual>
      <geometry>
        <box size="0.18 0.18 0.0215"/>/
      </geometry>
    </visual>
    <collision>
      <geometry>
        <box size="0.18 0.18 0.0215"/>
      </geometry>
      <contact_coefficients mu="0.3"/>
    </collision>
    <inertial>
      <origin xyz="0 0 0" rpy="0 0 0"/>
      <mass value="0.03"/>
      <inertia ixx="0.01" ixy="0.0" ixz="0.0" iyy="0.01" iyz="0.0" izz="0.01"/>
    </inertial>
  </link>

  <link name="intermediate_link0">
    <visual>
      <geometry>
        <box size="0.01 0.01 0.004"/>
      </geometry>
      <origin xyz="0 0 -0.002" rpy="0 0 0"/>
    </visual>
    <inertial>
      <mass value="0.0001"/>
      <inertia ixx="0.00001" ixy="0.0" ixz="0.0" iyy="0.00001" iyz="0.0" izz="0.00001"/>
    </inertial>
  </link>

  <link name="upper_leg0">
    <visual>
      <geometry>
        <cylinder radius="0.01" length="0.0623"/>
      </geometry>
      <origin xyz="0 0 -0.03115" rpy="0 0 0"/>
    </visual>
    <inertial>
      <mass value="0.01"/>
      <inertia ixx="0.001" ixy="0.0" ixz="0.0" iyy="0.001" iyz="0.0" izz="0.001"/>
    </inertial>
  </link>

  <link name="intermediate_link1">
    <visual>
      <geometry>
        <box size="0.001 0.001 0.004"/>
      </geometry>
      <origin xyz="0 0 -0.002" rpy="0 0 0"/>
    </visual>
    <inertial>
      <mass value="0.0001"/>
      <inertia ixx="0.00001" ixy="0.0" ixz="0.0" iyy="0.00001" iyz="0.0" izz="0.00001"/>
    </inertial>
  </link>

  <link name="upper_leg1">
    <visual>
      <geometry>
        <cylinder radius="0.01" length="0.0623"/>
      </geometry>
      <origin xyz="0 0 -0.03115" rpy="0 0 0"/>
    </visual>
    <inertial>
      <mass value="0.01"/>
      <inertia ixx="0.001" ixy="0.0" ixz="0.0" iyy="0.001" iyz="0.0" izz="0.001"/>
    </inertial>
  </link>

  <link name="intermediate_link2">
    <visual>
      <geometry>
        <box size="0.001 0.001 0.004"/>
      </geometry>
      <origin xyz="0 0 -0.002" rpy="0 0 0"/>
    </visual>
    <inertial>
      <mass value="0.0001"/>
      <inertia ixx="0.00001" ixy="0.0" ixz="0.0" iyy="0.00001" iyz="0.0" izz="0.00001"/>
    </inertial>
  </link>

  <link name="upper_leg2">
    <visual>
      <geometry>
        <cylinder radius="0.01" length="0.0623"/>
      </geometry>
      <origin xyz="0 0 -0.03115" rpy="0 0 0"/>
    </visual>
    <inertial>
      <mass value="0.01"/>
      <inertia ixx="0.001" ixy="0.0" ixz="0.0" iyy="0.001" iyz="0.0" izz="0.001"/>
    </inertial>
  </link>

  <link name="lower_leg0">
    <visual>
      <geometry>
        <cylinder radius="0.01" length="0.0496"/>
      </geometry>
      <origin xyz="0 0 -0.0248" rpy="0 0 0"/>
    </visual>
    <inertial>
      <mass value="0.01"/>
      <inertia ixx="0.001" ixy="0.0" ixz="0.0" iyy="0.001" iyz="0.0" izz="0.001"/>
    </inertial>
  </link>

  <link name="lower_leg1">
    <visual>
      <geometry>
        <cylinder radius="0.01" length="0.0496"/>
      </geometry>
      <origin xyz="0 0 -0.0248" rpy="0 0 0"/>
    </visual>
    <inertial>
      <mass value="0.01"/>
      <inertia ixx="0.001" ixy="0.0" ixz="0.0" iyy="0.001" iyz="0.0" izz="0.001"/>
    </inertial>
  </link>

  <link name="lower_leg2">
    <visual>
      <geometry>
        <cylinder radius="0.01" length="0.0496"/>
      </geometry>
      <origin xyz="0 0 -0.0248" rpy="0 0 0"/>
    </visual>
    <inertial>
      <mass value="0.01"/>
      <inertia ixx="0.001" ixy="0.0" ixz="0.0" iyy="0.001" iyz="0.0" izz="0.001"/>
    </inertial>
  </link>

  <link name="foot0">
    <visual>
      <geometry>
        <cylinder radius="0.03" length="0.0550"/>
      </geometry>
      <origin xyz="0 0 -0.0275" rpy="0 0 0"/>
    </visual>
    <collision>
      <geometry>
        <cylinder radius="0.03" length="0.0550"/>
      </geometry>
      <origin xyz="0 0 -0.0275" rpy="0 0 0"/>
    </collision>
    <inertial>
      <mass value="10"/>
      <inertia ixx="1.0" ixy="0.0" ixz="0.0" iyy="1.0" iyz="0.0" izz="1.0"/>
    </inertial>
  </link>

  <link name="foot1">
    <visual>
      <geometry>
        <cylinder radius="0.03" length="0.0550"/>
      </geometry>
      <origin xyz="0 0 -0.0275" rpy="0 0 0"/>
    </visual>
    <collision>
      <geometry>
        <cylinder radius="0.03" length="0.0550"/>
      </geometry>
      <origin xyz="0 0 -0.0275" rpy="0 0 0"/>
    </collision>
    <inertial>
      <mass value="10"/>
      <inertia ixx="1.0" ixy="0.0" ixz="0.0" iyy="1.0" iyz="0.0" izz="1.0"/>
    </inertial>
  </link>

  <link name="foot2">
    <visual>
      <geometry>
        <cylinder radius="0.03" length="0.0550"/>
      </geometry>
      <origin xyz="0 0 -0.0275" rpy="0 0 0"/>
    </visual>
    <collision>
      <geometry>
        <cylinder radius="0.03" length="0.0550"/>
      </geometry>
      <origin xyz="0 0 -0.0275" rpy="0 0 0"/>
    </collision>
    <inertial>
      <mass value="10"/>
      <inertia ixx="1.0" ixy="0.0" ixz="0.0" iyy="1.0" iyz="0.0" izz="1.0"/>
    </inertial>
  </link>

  <joint name="upper_leg_joint00" type="revolute">
    <parent link="plane"/>
    <child link="intermediate_link0"/>
    <axis xyz="1 0 0"/>
    <origin xyz="-0.01 0.07 -0.01075"/>
    <limit effort="300" velocity="0.1" lower="-3.14" upper="3.14"/>
    <dynamics damping="50" friction="0.01"/>
  </joint>

  <joint name="upper_leg_joint01" type="revolute">
    <parent link="intermediate_link0"/>
    <child link="upper_leg0"/>
    <axis xyz="0 1 0"/>
    <origin xyz="0 0 -0.004"/>
    <limit effort="300" velocity="0.1" lower="-3.14" upper="3.14"/>
    <dynamics damping="50" friction="0.01"/>
  </joint>

  <joint name="upper_leg_joint10" type="revolute">
    <parent link="plane"/>
    <child link="intermediate_link1"/>
    <axis xyz="-0.5 -0.866 0"/>
    <origin xyz="0.0656 -0.0263 -0.01075"/>
    <limit effort="300" velocity="0.1" lower="-3.14" upper="3.14"/>
    <dynamics damping="50" friction="0.01"/>
  </joint>

  <joint name="upper_leg_joint11" type="revolute">
    <parent link="intermediate_link1"/>
    <child link="upper_leg1"/>
    <axis xyz="0.866 0.5 0"/>
    <origin xyz="0 0 -0.004"/>
    <limit effort="300" velocity="0.1" lower="-3.14" upper="3.14"/>
    <dynamics damping="50" friction="0.01"/>
  </joint>

  <joint name="upper_leg_joint20" type="revolute">
    <parent link="plane"/>
    <child link="intermediate_link2"/>
    <axis xyz="-0.5 0.866 0"/>
    <origin xyz="-0.0556 -0.0437 -0.01075"/>
    <limit effort="300" velocity="0.1" lower="-3.14" upper="3.14"/>
    <dynamics damping="50" friction="0.01"/>
  </joint>

  <joint name="upper_leg_joint21" type="revolute">
    <parent link="intermediate_link2"/>
    <child link="upper_leg2"/>
    <axis xyz="0.866 0.5 0"/>
    <origin xyz="0 0 -0.004"/>
    <limit effort="300" velocity="0.1" lower="-3.14" upper="3.14"/>
    <dynamics damping="50" friction="0.01"/>
  </joint>

  <joint name="lower_leg_joint0" type="revolute">
    <parent link="upper_leg0"/>
    <child link="lower_leg0"/>
    <axis xyz="-1 0 0"/>
    <origin xyz="0 0 -0.0623"/>
    <limit effort="300" velocity="0.1" lower="0" upper="3.1"/>
    <dynamics damping="50" friction="0.01"/>
  </joint>

  <joint name="lower_leg_joint1" type="revolute">
    <parent link="upper_leg1"/>
    <child link="lower_leg1"/>
    <axis xyz="0.5 0.866 0"/>
    <origin xyz="0 0 -0.0623"/>
    <limit effort="300" velocity="0.1" lower="0" upper="3.1"/>
    <dynamics damping="50" friction="0.01"/>
  </joint>

  <joint name="lower_leg_joint2" type="revolute">
    <parent link="upper_leg2"/>
    <child link="lower_leg2"/>
    <axis xyz="0.5 -0.866 0"/>
    <origin xyz="0 0 -0.0623"/>
    <limit effort="300" velocity="0.1" lower="0" upper="3.1"/>
    <dynamics damping="50" friction="0.01"/>
  </joint>

  <joint name="foot_joint0" type="revolute">
    <parent link="lower_leg0"/>
    <child link="foot0"/>
    <axis xyz="1 0 0"/>
    <origin xyz="0 0 -0.0496"/>
    <limit effort="300" velocity="0.1" lower="0" upper="1.6"/>
    <dynamics damping="50" friction="0.01"/>
  </joint>

  <joint name="foot_joint1" type="revolute">
    <parent link="lower_leg1"/>
    <child link="foot1"/>
    <axis xyz="-0.5 -0.866 0"/>
    <origin xyz="0 0 -0.0496"/>
    <limit effort="300" velocity="0.1" lower="0" upper="1.6"/>
    <dynamics damping="50" friction="0.01"/>
  </joint>

  <joint name="foot_joint2" type="revolute">
    <parent link="lower_leg2"/>
    <child link="foot2"/>
    <axis xyz="-0.5 0.866 0"/>
    <origin xyz="0 0 -0.0496"/>
    <limit effort="300" velocity="0.1" lower="0" upper="1.6"/>
    <dynamics damping="50" friction="0.01"/>
  </joint>

</robot>
